<?xml version="1.0"?>
<!--
  ScottBot URDF — UCR food delivery robot
  Mecanum-wheel holonomic base with camera and 2-D LIDAR for Gazebo simulation.
-->
<robot xmlns:xacro="http://www.ros.org/wiki/xacro" name="scottbot">

  <!-- ==================== Properties ==================== -->
  <xacro:property name="body_length"  value="0.50"/>
  <xacro:property name="body_width"   value="0.35"/>
  <xacro:property name="body_height"  value="0.20"/>
  <xacro:property name="body_mass"    value="10.0"/>

  <xacro:property name="wheel_radius" value="0.075"/>
  <xacro:property name="wheel_width"  value="0.04"/>
  <xacro:property name="wheel_mass"   value="0.5"/>
  <xacro:property name="wheel_separation" value="0.40"/>  <!-- lateral distance between left & right wheels -->
  <xacro:property name="wheelbase"          value="0.34"/>  <!-- longitudinal distance between front & rear axles -->

  <!-- ==================== Materials ==================== -->
  <material name="blue">
    <color rgba="0.2 0.4 0.8 1.0"/>
  </material>
  <material name="dark_grey">
    <color rgba="0.3 0.3 0.3 1.0"/>
  </material>
  <material name="black">
    <color rgba="0.1 0.1 0.1 1.0"/>
  </material>

  <!-- ==================== Macros ==================== -->

  <!-- Inertia helpers -->
  <xacro:macro name="box_inertia" params="m x y z">
    <inertial>
      <mass value="${m}"/>
      <inertia ixx="${m*(y*y+z*z)/12}" ixy="0" ixz="0"
               iyy="${m*(x*x+z*z)/12}" iyz="0"
               izz="${m*(x*x+y*y)/12}"/>
    </inertial>
  </xacro:macro>

  <xacro:macro name="cylinder_inertia" params="m r h">
    <inertial>
      <mass value="${m}"/>
      <inertia ixx="${m*(3*r*r+h*h)/12}" ixy="0" ixz="0"
               iyy="${m*(3*r*r+h*h)/12}" iyz="0"
               izz="${m*r*r/2}"/>
    </inertial>
  </xacro:macro>

  <xacro:macro name="sphere_inertia" params="m r">
    <inertial>
      <mass value="${m}"/>
      <inertia ixx="${2*m*r*r/5}" ixy="0" ixz="0"
               iyy="${2*m*r*r/5}" iyz="0"
               izz="${2*m*r*r/5}"/>
    </inertial>
  </xacro:macro>

  <!-- Mecanum wheel macro (4 corners) -->
  <xacro:macro name="mecanum_wheel" params="prefix x_offset y_offset">
    <link name="${prefix}_wheel_link">
      <visual>
        <geometry>
          <cylinder radius="${wheel_radius}" length="${wheel_width}"/>
        </geometry>
        <material name="dark_grey"/>
      </visual>
      <collision>
        <geometry>
          <sphere radius="${wheel_radius}"/>
        </geometry>
        <surface>
          <friction>
            <ode>
              <mu>0.1</mu>
              <mu2>0.1</mu2>
              <slip1>1.0</slip1>
              <slip2>1.0</slip2>
            </ode>
          </friction>
        </surface>
      </collision>
      <xacro:cylinder_inertia m="${wheel_mass}" r="${wheel_radius}" h="${wheel_width}"/>
    </link>

    <joint name="${prefix}_wheel_joint" type="continuous">
      <parent link="base_link"/>
      <child link="${prefix}_wheel_link"/>
      <origin xyz="${x_offset} ${y_offset} 0" rpy="${-pi/2} 0 0"/>
      <axis xyz="0 0 1"/>
      <dynamics damping="0.05" friction="0.05"/>
    </joint>
  </xacro:macro>

  <!-- ==================== Links & Joints ==================== -->

  <!-- Footprint (ground-level reference) -->
  <link name="base_footprint"/>

  <!-- Base link (chassis) -->
  <link name="base_link">
    <visual>
      <geometry>
        <box size="${body_length} ${body_width} ${body_height}"/>
      </geometry>
      <material name="blue"/>
    </visual>
    <collision>
      <geometry>
        <box size="${body_length} ${body_width} ${body_height}"/>
      </geometry>
    </collision>
    <xacro:box_inertia m="${body_mass}" x="${body_length}" y="${body_width}" z="${body_height}"/>
  </link>

  <joint name="base_footprint_joint" type="fixed">
    <parent link="base_footprint"/>
    <child link="base_link"/>
    <origin xyz="0 0 ${wheel_radius + body_height/2}" rpy="0 0 0"/>
  </joint>

  <!-- Mecanum wheels (front-left, front-right, rear-left, rear-right) -->
  <xacro:mecanum_wheel prefix="front_left"  x_offset="${wheelbase/2}"  y_offset="${wheel_separation/2}"/>
  <xacro:mecanum_wheel prefix="front_right" x_offset="${wheelbase/2}"  y_offset="${-wheel_separation/2}"/>
  <xacro:mecanum_wheel prefix="rear_left"   x_offset="${-wheelbase/2}" y_offset="${wheel_separation/2}"/>
  <xacro:mecanum_wheel prefix="rear_right"  x_offset="${-wheelbase/2}" y_offset="${-wheel_separation/2}"/>

  <!-- ==================== Sensors ==================== -->

  <!-- Camera -->
  <link name="camera_link">
    <visual>
      <geometry>
        <box size="0.03 0.08 0.03"/>
      </geometry>
      <material name="black"/>
    </visual>
    <collision>
      <geometry>
        <box size="0.03 0.08 0.03"/>
      </geometry>
    </collision>
    <xacro:box_inertia m="0.05" x="0.03" y="0.08" z="0.03"/>
  </link>

  <joint name="camera_joint" type="fixed">
    <parent link="base_link"/>
    <child link="camera_link"/>
    <origin xyz="${body_length/2} 0 ${body_height/2 - 0.015}" rpy="0 0 0"/>
  </joint>

  <!-- Camera optical frame (Z-forward convention) -->
  <link name="camera_optical_link"/>

  <joint name="camera_optical_joint" type="fixed">
    <parent link="camera_link"/>
    <child link="camera_optical_link"/>
    <origin xyz="0 0 0" rpy="${-pi/2} 0 ${-pi/2}"/>
  </joint>

  <!-- LIDAR -->
  <link name="lidar_link">
    <visual>
      <geometry>
        <cylinder radius="0.035" length="0.04"/>
      </geometry>
      <material name="dark_grey"/>
    </visual>
    <collision>
      <geometry>
        <cylinder radius="0.035" length="0.04"/>
      </geometry>
    </collision>
    <xacro:cylinder_inertia m="0.15" r="0.035" h="0.04"/>
  </link>

  <joint name="lidar_joint" type="fixed">
    <parent link="base_link"/>
    <child link="lidar_link"/>
    <origin xyz="0 0 ${body_height/2 + 0.02}" rpy="0 0 0"/>
  </joint>

  <!-- ==================== Gazebo-specific ==================== -->

  <!-- Chassis colour in Gazebo (OGRE material) -->
  <gazebo reference="base_link">
    <material>Gazebo/Blue</material>
  </gazebo>
  <gazebo reference="front_left_wheel_link">
    <material>Gazebo/DarkGrey</material>
    <mu1>0.1</mu1>
    <mu2>0.1</mu2>
  </gazebo>
  <gazebo reference="front_right_wheel_link">
    <material>Gazebo/DarkGrey</material>
    <mu1>0.1</mu1>
    <mu2>0.1</mu2>
  </gazebo>
  <gazebo reference="rear_left_wheel_link">
    <material>Gazebo/DarkGrey</material>
    <mu1>0.1</mu1>
    <mu2>0.1</mu2>
  </gazebo>
  <gazebo reference="rear_right_wheel_link">
    <material>Gazebo/DarkGrey</material>
    <mu1>0.1</mu1>
    <mu2>0.1</mu2>
  </gazebo>

  <!-- ===== Planar-move controller for mecanum / holonomic drive ===== -->
  <!--
    libgazebo_ros_planar_move gives true omnidirectional motion:
    it listens on /cmd_vel (linear.x, linear.y, angular.z) and
    publishes /odom, exactly like a real mecanum base would.
  -->
  <gazebo>
    <plugin name="planar_move" filename="libgazebo_ros_planar_move.so">
      <ros>
        <namespace>/</namespace>
      </ros>
      <update_rate>50</update_rate>

      <command_topic>cmd_vel</command_topic>
      <odometry_topic>odom</odometry_topic>
      <odometry_frame>odom</odometry_frame>
      <robot_base_frame>base_footprint</robot_base_frame>

      <publish_odom>true</publish_odom>
      <publish_odom_tf>true</publish_odom_tf>
    </plugin>
  </gazebo>

  <!-- ===== Camera plugin (replaces camera_node) ===== -->
  <gazebo reference="camera_link">
    <sensor name="camera_sensor" type="camera">
      <always_on>true</always_on>
      <update_rate>10.0</update_rate>
      <visualize>true</visualize>
      <camera>
        <horizontal_fov>1.089</horizontal_fov>
        <image>
          <width>640</width>
          <height>480</height>
          <format>R8G8B8</format>
        </image>
        <clip>
          <near>0.05</near>
          <far>50.0</far>
        </clip>
      </camera>
      <plugin name="camera_plugin" filename="libgazebo_ros_camera.so">
        <ros>
          <namespace>/</namespace>
        </ros>
        <camera_name>camera</camera_name>
        <frame_name>camera_optical_link</frame_name>
        <hack_baseline>0.0</hack_baseline>
      </plugin>
    </sensor>
  </gazebo>

  <!-- ===== LIDAR plugin (replaces lidar_node) ===== -->
  <gazebo reference="lidar_link">
    <sensor name="lidar_sensor" type="ray">
      <always_on>true</always_on>
      <update_rate>10.0</update_rate>
      <visualize>true</visualize>
      <ray>
        <scan>
          <horizontal>
            <samples>360</samples>
            <resolution>1</resolution>
            <min_angle>-3.14159</min_angle>
            <max_angle>3.14159</max_angle>
          </horizontal>
        </scan>
        <range>
          <min>0.12</min>
          <max>12.0</max>
          <resolution>0.01</resolution>
        </range>
        <noise>
          <type>gaussian</type>
          <mean>0.0</mean>
          <stddev>0.01</stddev>
        </noise>
      </ray>
      <plugin name="lidar_plugin" filename="libgazebo_ros_ray_sensor.so">
        <ros>
          <namespace>/</namespace>
          <remapping>~/out:=scan</remapping>
        </ros>
        <output_type>sensor_msgs/LaserScan</output_type>
        <frame_name>lidar_link</frame_name>
      </plugin>
    </sensor>
  </gazebo>

</robot>
